<?xml version="1.0" encoding="utf-8"?>
<!-- =================================================================================== -->
<!-- |    This document was autogenerated by xacro from sobit_pro.urdf.xacro           | -->
<!-- |    EDITING THIS FILE BY HAND IS NOT RECOMMENDED                                 | -->
<!-- =================================================================================== -->
<robot name="sobit_pro" xmlns:controller="http://playerstage.sourceforge.net/gazebo/xmlschema/#controller" xmlns:interface="http://playerstage.sourceforge.net/gazebo/xmlschema/#interface" xmlns:sensor="http://playerstage.sourceforge.net/gazebo/xmlschema/#sensor">
  <material name="wheel">
    <color rgba="0.2 0.2 0.2 1.0"/>
  </material>
  <material name="black">
    <color rgba="0.1 0.1 0.1 1.0"/>
  </material>
  <material name="red">
    <color rgba="1.0 0.0 0.0 1.0"/>
  </material>
  <material name="green">
    <color rgba="0.0 1.0 0.0 1.0"/>
  </material>
  <material name="blue">
    <color rgba="0.0 0.0 1.0 1.0"/>
  </material>
  <!--
  <xacro:include filename="$(find sobit_pro_description)/urdf/arm/arm.urdf.xacro" />
  <xacro:include filename="$(find sobit_pro_description)/urdf/gripper/gripper.urdf.xacro" />
  <xacro:include filename="$(find sobit_pro_description)/urdf/head/head.urdf.xacro" />
  <xacro:include filename="$(find sobit_pro_description)/urdf/pole/pole.urdf.xacro" />
  <xacro:include filename="$(find sobit_pro_description)/urdf/sensor/sensor.urdf.xacro" />
  -->
  <link name="base_footprint"/>
  <joint name="base_joint" type="fixed">
    <parent link="base_footprint"/>
    <child link="base_link"/>
    <origin rpy="0 0 0" xyz="0 0 0.143"/>
  </joint>
  <link name="base_link">
    <visual>
      <origin rpy="1.570796327 0 0" xyz="0 0 -0.143"/>
      <geometry>
        <mesh filename="package://sobit_pro_description/meshes/base/sobit_pro_body.dae"/>
      </geometry>
    </visual>
  </link>
  <!--steering-->
  <joint name="steer_b_l_joint" type="revolute">
    <parent link="base_link"/>
    <child link="steer_b_l_link"/>
    <origin rpy="0 0 0" xyz="0.15841 0.15841 0.07"/>
    <axis xyz="0 0 1"/>
    <limit effort="10" lower="-1.5" upper="1.5" velocity="10"/>
    <dynamics damping="0.2" friction="0"/>
  </joint>
  <link name="steer_b_l_link">
    <visual>
      <origin rpy="1.570796327 0 0" xyz="-0.15841 -0.15841 -0.213"/>
      <geometry>
        <mesh filename="package://sobit_pro_description/meshes/wheel/sobit_pro_steer_b_l.dae"/>
      </geometry>
    </visual>
  </link>
  <joint name="steer_b_r_joint" type="revolute">
    <parent link="base_link"/>
    <child link="steer_b_r_link"/>
    <origin rpy="0 0 0" xyz="-0.15841 0.15841 0.07"/>
    <axis xyz="0 0 1"/>
    <limit effort="10" lower="-1.5" upper="1.5" velocity="10"/>
    <dynamics damping="0.2" friction="0"/>
  </joint>
  <link name="steer_b_r_link">
    <visual>
      <origin rpy="1.570796327 0 0" xyz="0.15841 -0.15841 -0.213"/>
      <geometry>
        <mesh filename="package://sobit_pro_description/meshes/wheel/sobit_pro_steer_b_r.dae"/>
      </geometry>
    </visual>
  </link>
  <joint name="steer_f_l_joint" type="revolute">
    <parent link="base_link"/>
    <child link="steer_f_l_link"/>
    <origin rpy="0 0 0" xyz="0.15841 -0.15841 0.07"/>
    <axis xyz="0 0 1"/>
    <limit effort="10" lower="-1.5" upper="1.5" velocity="10"/>
    <dynamics damping="0.2" friction="0"/>
  </joint>
  <link name="steer_f_l_link">
    <visual>
      <origin rpy="1.570796327 0 0" xyz="-0.15841 0.15841 -0.213"/>
      <geometry>
        <mesh filename="package://sobit_pro_description/meshes/wheel/sobit_pro_steer_f_l.dae"/>
      </geometry>
    </visual>
  </link>
  <joint name="steer_f_r_joint" type="revolute">
    <parent link="base_link"/>
    <child link="steer_f_r_link"/>
    <origin rpy="0 0 0" xyz="-0.15841 -0.15841 0.07"/>
    <axis xyz="0 0 1"/>
    <limit effort="10" lower="-1.5" upper="1.5" velocity="10"/>
    <dynamics damping="0.2" friction="0"/>
  </joint>
  <link name="steer_f_r_link">
    <visual>
      <origin rpy="1.570796327 0 0" xyz="0.15841 0.15841 -0.213"/>
      <geometry>
        <mesh filename="package://sobit_pro_description/meshes/wheel/sobit_pro_steer_f_r.dae"/>
      </geometry>
    </visual>
  </link>
  <!--wheel-->
  <joint name="wheel_b_l_joint" type="continuous">
    <parent link="steer_b_l_link"/>
    <child link="wheel_b_l_link"/>
    <origin rpy="0 0 0" xyz="0 0 -0.1414"/>
    <axis xyz="1 1 0"/>
  </joint>
  <link name="wheel_b_l_link">
    <visual>
      <origin rpy="1.570796327 0 0" xyz="-0.15841 -0.15841 -0.072"/>
      <geometry>
        <mesh filename="package://sobit_pro_description/meshes/wheel/sobit_pro_wheel_b_l.dae"/>
      </geometry>
    </visual>
  </link>
  <joint name="wheel_b_r_joint" type="continuous">
    <parent link="steer_b_r_link"/>
    <child link="wheel_b_r_link"/>
    <origin rpy="0 0 0" xyz="0 0 -0.1414"/>
    <axis xyz="-1 1 0"/>
  </joint>
  <link name="wheel_b_r_link">
    <visual>
      <origin rpy="1.570796327 0 0" xyz="0.15841 -0.15841 -0.072"/>
      <geometry>
        <mesh filename="package://sobit_pro_description/meshes/wheel/sobit_pro_wheel_b_r.dae"/>
      </geometry>
    </visual>
  </link>
  <joint name="wheel_f_l_joint" type="continuous">
    <parent link="steer_f_l_link"/>
    <child link="wheel_f_l_link"/>
    <origin rpy="0 0 0" xyz="0 0 -0.1414"/>
    <axis xyz="-1 1 0"/>
  </joint>
  <link name="wheel_f_l_link">
    <visual>
      <origin rpy="1.570796327 0 0" xyz="-0.15841 0.15841 -0.072"/>
      <geometry>
        <mesh filename="package://sobit_pro_description/meshes/wheel/sobit_pro_wheel_f_l.dae"/>
      </geometry>
    </visual>
  </link>
  <joint name="wheel_f_r_joint" type="continuous">
    <parent link="steer_f_r_link"/>
    <child link="wheel_f_r_link"/>
    <origin rpy="0 0 0" xyz="0 0 -0.1414"/>
    <axis xyz="1 1 0"/>
  </joint>
  <link name="wheel_f_r_link">
    <visual>
      <origin rpy="1.570796327 0 0" xyz="0.15841 0.15841 -0.072"/>
      <geometry>
        <mesh filename="package://sobit_pro_description/meshes/wheel/sobit_pro_wheel_f_r.dae"/>
      </geometry>
    </visual>
  </link>
  <joint name="arm_base_joint" type="fixed">
    <parent link="base_link"/>
    <child link="arm_base_link"/>
    <origin rpy="0 0 0" xyz="0 -0.221 0.5995"/>
  </joint>
  <link name="arm_base_link">
    <visual>
      <origin rpy="1.570796327 0 0" xyz="0 0 0"/>
      <geometry>
        <mesh filename="package://sobit_pro_description/meshes/arm/sobit_pro_arm_base.dae"/>
      </geometry>
    </visual>
  </link>
  <joint name="arm1_joint" type="revolute">
    <parent link="arm_base_link"/>
    <child link="arm1_link"/>
    <origin rpy="1.5707963268 0 0" xyz="0 0 0"/>
    <axis xyz="-1 0 0"/>
    <limit effort="10" lower="-1.5707963268" upper="1.5707963268" velocity="10"/>
    <dynamics damping="0.2" friction="0"/>
  </joint>
  <link name="arm1_link">
    <visual>
      <origin rpy="1.570796327 0 0" xyz="0 0 0"/>
      <geometry>
        <mesh filename="package://sobit_pro_description/meshes/arm/sobit_pro_arm1.dae"/>
      </geometry>
    </visual>
  </link>
  <joint name="arm2_joint" type="revolute">
    <parent link="arm1_link"/>
    <child link="arm2_link"/>
    <origin rpy="-1.137 0 0" xyz="0 0 0.15"/>
    <axis xyz="-1 0 0"/>
    <limit effort="10" lower="-1.5707963268" upper="1.5707963268" velocity="10"/>
    <dynamics damping="0.2" friction="0"/>
  </joint>
  <link name="arm2_link">
    <visual>
      <origin rpy="1.570796327 0 0" xyz="0 0 -0.15"/>
      <geometry>
        <mesh filename="package://sobit_pro_description/meshes/arm/sobit_pro_arm2.dae"/>
      </geometry>
    </visual>
  </link>
  <joint name="arm3_joint" type="revolute">
    <parent link="arm2_link"/>
    <child link="arm3_link"/>
    <origin rpy="-1.30 0 0" xyz="0 -0.13594617 0.06339274"/>
    <axis xyz="-1 0 0"/>
    <limit effort="10" lower="-1.5707963268" upper="1.5707963268" velocity="10"/>
    <dynamics damping="0.2" friction="0"/>
  </joint>
  <link name="arm3_link">
    <visual>
      <origin rpy="1.570796327 0 0" xyz="0 0.13594617 -0.21339274"/>
      <geometry>
        <mesh filename="package://sobit_pro_description/meshes/arm/sobit_pro_arm3.dae"/>
      </geometry>
    </visual>
  </link>
  <joint name="arm4_joint" type="revolute">
    <parent link="arm3_link"/>
    <child link="arm4_link"/>
    <origin rpy="0.87 0 0" xyz="0 -0.09641814 -0.11490667"/>
    <axis xyz="-1 0 0"/>
    <limit effort="10" lower="-1.5707963268" upper="1.5707963268" velocity="10"/>
    <dynamics damping="0.2" friction="0"/>
  </joint>
  <link name="arm4_link">
    <visual>
      <origin rpy="1.570796327 0 0" xyz="0 0.23236431 -0.09848607"/>
      <geometry>
        <mesh filename="package://sobit_pro_description/meshes/arm/sobit_pro_arm4.dae"/>
      </geometry>
    </visual>
  </link>
  <transmission name="arm1_joint_transmission">
    <type>transmission_interface/SimpleTransmission</type>
    <joint name="arm1_joint">
      <hardwareInterface>PositionJointInterface</hardwareInterface>
    </joint>
    <actuator name="arm1_joint_actuator">
      <hardwareInterface>PositionJointInterface</hardwareInterface>
      <mechanicalReduction>1</mechanicalReduction>
    </actuator>
  </transmission>
  <transmission name="arm2_joint_transmission">
    <type>transmission_interface/SimpleTransmission</type>
    <joint name="arm2_joint">
      <hardwareInterface>PositionJointInterface</hardwareInterface>
    </joint>
    <actuator name="arm2_joint_actuator">
      <hardwareInterface>PositionJointInterface</hardwareInterface>
      <mechanicalReduction>1</mechanicalReduction>
    </actuator>
  </transmission>
  <transmission name="arm3_joint_transmission">
    <type>transmission_interface/SimpleTransmission</type>
    <joint name="arm3_joint">
      <hardwareInterface>PositionJointInterface</hardwareInterface>
    </joint>
    <actuator name="arm3_joint_actuator">
      <hardwareInterface>PositionJointInterface</hardwareInterface>
      <mechanicalReduction>1</mechanicalReduction>
    </actuator>
  </transmission>
  <transmission name="arm4_joint_transmission">
    <type>transmission_interface/SimpleTransmission</type>
    <joint name="arm4_joint">
      <hardwareInterface>PositionJointInterface</hardwareInterface>
    </joint>
    <actuator name="arm4_joint_actuator">
      <hardwareInterface>PositionJointInterface</hardwareInterface>
      <mechanicalReduction>1</mechanicalReduction>
    </actuator>
  </transmission>
  <joint name="gripper_joint" type="revolute">
    <parent link="arm4_link"/>
    <child link="gripper_link"/>
    <origin rpy="0 0 0" xyz="0.0 0.0 0.0"/>
    <axis xyz="0 0 1"/>
    <limit effort="1" lower="-1.570796327" upper="0" velocity="1"/>
  </joint>
  <link name="gripper_link"/>
  <joint name="gripper_inner_r_joint" type="revolute">
    <parent link="arm4_link"/>
    <child link="gripper_inner_r_link"/>
    <origin rpy="0 0 0" xyz="-0.015 -0.07811569 0.02333593"/>
    <axis xyz="0 0 1"/>
    <limit effort="1" lower="-1.570796327" upper="0" velocity="1"/>
    <mimic joint="gripper_joint" multiplier="1.0" offset="0"/>
  </joint>
  <link name="gripper_inner_r_link">
    <visual>
      <origin rpy="1.570796327 0 0" xyz="0.015 0.31048 -0.121822"/>
      <geometry>
        <mesh filename="package://sobit_pro_description/meshes/gripper/sobit_pro_gripper_i_r.dae"/>
      </geometry>
    </visual>
  </link>
  <joint name="gripper_inner_l_joint" type="revolute">
    <parent link="arm4_link"/>
    <child link="gripper_inner_l_link"/>
    <origin rpy="0 0 0" xyz="0.015 -0.07811569 0.02333593"/>
    <axis xyz="0 0 1"/>
    <limit effort="1" lower="-1.570796327" upper="0" velocity="1"/>
    <mimic joint="gripper_joint" multiplier="-1.0" offset="0"/>
  </joint>
  <link name="gripper_inner_l_link">
    <visual>
      <origin rpy="1.570796327 0 0" xyz="-0.015 0.31048 -0.121822"/>
      <geometry>
        <mesh filename="package://sobit_pro_description/meshes/gripper/sobit_pro_gripper_i_l.dae"/>
      </geometry>
    </visual>
  </link>
  <joint name="gripper_outer_r_joint" type="revolute">
    <parent link="arm4_link"/>
    <child link="gripper_outer_r_link"/>
    <origin rpy="0 0 0" xyz="-0.04 -0.0580698 0.02333593"/>
    <axis xyz="0 0 1"/>
    <limit effort="1" lower="-1.570796327" upper="0" velocity="1"/>
    <mimic joint="gripper_joint" multiplier="1.12" offset="0"/>
  </joint>
  <link name="gripper_outer_r_link">
    <visual>
      <origin rpy="1.570796327 0 0" xyz="0.04 0.29043411 -0.121822"/>
      <geometry>
        <mesh filename="package://sobit_pro_description/meshes/gripper/sobit_pro_gripper_o_r.dae"/>
      </geometry>
    </visual>
  </link>
  <joint name="gripper_outer_l_joint" type="revolute">
    <parent link="arm4_link"/>
    <child link="gripper_outer_l_link"/>
    <origin rpy="0 0 0" xyz="0.04 -0.0580698 0.02333593"/>
    <axis xyz="0 0 1"/>
    <limit effort="1" lower="-1.570796327" upper="0" velocity="1"/>
    <mimic joint="gripper_joint" multiplier="-1.12" offset="0"/>
  </joint>
  <link name="gripper_outer_l_link">
    <visual>
      <origin rpy="1.570796327 0 0" xyz="-0.04 0.29043411 -0.121822"/>
      <geometry>
        <mesh filename="package://sobit_pro_description/meshes/gripper/sobit_pro_gripper_o_l.dae"/>
      </geometry>
    </visual>
  </link>
  <joint name="finger_r_joint" type="revolute">
    <parent link="gripper_inner_r_link"/>
    <child link="finger_r_link"/>
    <origin rpy="0 0 0" xyz="0 -0.080001 0"/>
    <axis xyz="0 0 1"/>
    <limit effort="1" lower="-1.570796327" upper="0" velocity="1"/>
    <mimic joint="gripper_joint" multiplier="-0.84" offset="0"/>
  </joint>
  <link name="finger_r_link">
    <visual>
      <origin rpy="1.570796327 0 0" xyz="0.015 0.390481 -0.121822"/>
      <geometry>
        <mesh filename="package://sobit_pro_description/meshes/gripper/sobit_pro_finger_r.dae"/>
      </geometry>
    </visual>
  </link>
  <joint name="finger_l_joint" type="revolute">
    <parent link="gripper_inner_l_link"/>
    <child link="finger_l_link"/>
    <origin rpy="0 0 0" xyz="0 -0.080001 0"/>
    <axis xyz="0 0 1"/>
    <limit effort="1" lower="-1.570796327" upper="0" velocity="1"/>
    <mimic joint="gripper_joint" multiplier="0.84" offset="0"/>
  </joint>
  <link name="finger_l_link">
    <visual>
      <origin rpy="1.570796327 0 0" xyz="-0.015 0.390481 -0.121822"/>
      <geometry>
        <mesh filename="package://sobit_pro_description/meshes/gripper/sobit_pro_finger_l.dae"/>
      </geometry>
    </visual>
  </link>
  <transmission name="gripper_joint_transmission">
    <type>transmission_interface/SimpleTransmission</type>
    <joint name="gripper_joint">
      <hardwareInterface>PositionJointInterface</hardwareInterface>
    </joint>
    <actuator name="gripper_joint_actuator">
      <hardwareInterface>PositionJointInterface</hardwareInterface>
      <mechanicalReduction>1</mechanicalReduction>
    </actuator>
  </transmission>
  <joint name="head_camera_pan_joint" type="revolute">
    <parent link="base_link"/>
    <child link="head_camera_pan_link"/>
    <origin rpy="0 0 0" xyz="0 -0.12985 1.117"/>
    <axis xyz="0 0 1"/>
    <limit effort="10" lower="-1.5707963268" upper="1.5707963268" velocity="10"/>
    <dynamics damping="0.2" friction="0"/>
  </joint>
  <link name="head_camera_pan_link">
    <visual>
      <origin rpy="1.570796327 0 0" xyz="0 0 -0.019"/>
      <geometry>
        <mesh filename="package://sobit_pro_description/meshes/head/sobit_pro_head_pan.dae"/>
      </geometry>
    </visual>
  </link>
  <joint name="head_camera_tilt_joint" type="revolute">
    <parent link="head_camera_pan_link"/>
    <child link="head_camera_tilt_link"/>
    <origin rpy="0 0 0" xyz="0 0 0.041"/>
    <axis xyz="-1 0 0"/>
    <limit effort="10" lower="-1.5707963268" upper="1.5707963268" velocity="10"/>
    <dynamics damping="0.2" friction="0"/>
  </joint>
  <link name="head_camera_tilt_link"/>
  <transmission name="head_camera_pan_joint_transmission">
    <type>transmission_interface/SimpleTransmission</type>
    <joint name="head_camera_pan_joint">
      <hardwareInterface>PositionJointInterface</hardwareInterface>
    </joint>
    <actuator name="head_camera_pan_joint_actuator">
      <hardwareInterface>PositionJointInterface</hardwareInterface>
      <mechanicalReduction>1</mechanicalReduction>
    </actuator>
  </transmission>
  <transmission name="head_camera_tilt_joint_transmission">
    <type>transmission_interface/SimpleTransmission</type>
    <joint name="head_camera_tilt_joint">
      <hardwareInterface>PositionJointInterface</hardwareInterface>
    </joint>
    <actuator name="head_camera_tilt_joint_actuator">
      <hardwareInterface>PositionJointInterface</hardwareInterface>
      <mechanicalReduction>1</mechanicalReduction>
    </actuator>
  </transmission>
  <joint name="head_camera_joint" type="fixed">
    <parent link="head_camera_tilt_link"/>
    <child link="head_camera_link"/>
    <origin rpy="0 0 0" xyz="0 0 0"/>
  </joint>
  <link name="head_camera_link">
    <visual>
      <origin rpy="1.570796327 0 0" xyz="0 0 -0.06"/>
      <geometry>
        <mesh filename="package://sobit_pro_description/meshes/sensor/azure_kinect.dae"/>
      </geometry>
    </visual>
  </link>
  <!--
  <stack_hexagons parent="base_link" />
  <xacro:arm prefix="arm" parent="plate_top_link"/>
  <xacro:hand prefix="hand_motor" parent="wrist_flex_link"/>
  <xacro:pole parent="plate_top_link"/>
  <xacro:xtion_motor prefix="xtion" parent="base_pole_link"/>
  <xacro:sensor_asus_xtion_pro parent="xtion_double_sided_tape_link"/>
  <xacro:mic parent="base_pole_link"/>
  <xacro:matrix parent="base_pole_link"/>
  <xacro:urg parent="base_link"/>
  -->
</robot>

