<?xml version="1.0" encoding="UTF-8" ?>
<robot name="gripper"
  xmlns:xacro="http://ros.org/wiki/xacro">

  <xacro:include filename="$(find sobit_pro_description)/urdf/gripper/gripper.transmission.xacro" />

  <xacro:macro name="gripper" params="prefix_grip prefix_finger parent">

    <joint name="${prefix_grip}_joint" type="revolute">
      <parent link="${parent}" />
      <child link="${prefix_grip}_link" />
      <origin xyz="0.0 0.0 0.0" rpy="0 0 0" />
      <axis xyz="0 0 1" />
      <limit lower="-1.570796327" upper="0" effort="1" velocity="1"/>
    </joint>

    <link name="${prefix_grip}_link"/>

    <joint name="${prefix_grip}_inner_r_joint" type="revolute">
      <parent link="${parent}" />
      <child link="${prefix_grip}_inner_r_link" />
      <origin xyz="-0.015 -0.07811569 0.02333593" rpy="0 0 0" />
      <axis xyz="0 0 1" />
      <limit lower="-1.570796327" upper="0" effort="1" velocity="1"/>
      <mimic joint="${prefix_grip}_joint" multiplier="1.0" offset="0"/>
    </joint>

    <link name="${prefix_grip}_inner_r_link">
      <visual>
        <origin xyz="0.015 0.31048 -0.121822" rpy="1.570796327 0 0" />
        <geometry>
          <mesh filename="package://sobit_pro_description/meshes/gripper/sobit_pro_gripper_i_r.dae"/>
        </geometry>
      </visual>
    </link>

    <joint name="${prefix_grip}_inner_l_joint" type="revolute">
      <parent link="${parent}" />
      <child link="${prefix_grip}_inner_l_link" />
      <origin xyz="0.015 -0.07811569 0.02333593" rpy="0 0 0" />
      <axis xyz="0 0 1" />
      <limit lower="-1.570796327" upper="0" effort="1" velocity="1"/>
      <mimic joint="${prefix_grip}_joint" multiplier="-1.0" offset="0"/>
    </joint>

    <link name="${prefix_grip}_inner_l_link">
      <visual>
        <origin xyz="-0.015 0.31048 -0.121822" rpy="1.570796327 0 0" />
        <geometry>
          <mesh filename="package://sobit_pro_description/meshes/gripper/sobit_pro_gripper_i_l.dae"/>
        </geometry>
      </visual>
    </link>

    <joint name="${prefix_grip}_outer_r_joint" type="revolute">
      <parent link="${parent}" />
      <child link="${prefix_grip}_outer_r_link" />
      <origin xyz="-0.04 -0.0580698 0.02333593" rpy="0 0 0" />
      <axis xyz="0 0 1" />
      <limit lower="-1.570796327" upper="0" effort="1" velocity="1"/>
      <mimic joint="${prefix_grip}_joint" multiplier="1.12" offset="0"/>
    </joint>

    <link name="${prefix_grip}_outer_r_link">
      <visual>
        <origin xyz="0.04 0.29043411 -0.121822" rpy="1.570796327 0 0" />
        <geometry>
          <mesh filename="package://sobit_pro_description/meshes/gripper/sobit_pro_gripper_o_r.dae"/>
        </geometry>
      </visual>
    </link>

    <joint name="${prefix_grip}_outer_l_joint" type="revolute">
      <parent link="${parent}" />
      <child link="${prefix_grip}_outer_l_link" />
      <origin xyz="0.04 -0.0580698 0.02333593" rpy="0 0 0" />
      <axis xyz="0 0 1" />
      <limit lower="-1.570796327" upper="0" effort="1" velocity="1"/>
      <mimic joint="${prefix_grip}_joint" multiplier="-1.12" offset="0"/>
    </joint>

    <link name="${prefix_grip}_outer_l_link">
      <visual>
        <origin xyz="-0.04 0.29043411 -0.121822" rpy="1.570796327 0 0" />
        <geometry>
          <mesh filename="package://sobit_pro_description/meshes/gripper/sobit_pro_gripper_o_l.dae"/>
        </geometry>
      </visual>
    </link>

    <joint name="${prefix_finger}_r_joint" type="revolute">
      <parent link="${prefix_grip}_inner_r_link" />
      <child link="${prefix_finger}_r_link" />
      <origin xyz="0 -0.080001 0" rpy="0 0 0" />
      <axis xyz="0 0 1" />
      <limit lower="-1.570796327" upper="0" effort="1" velocity="1"/>
      <mimic joint="${prefix_grip}_joint" multiplier="-0.84" offset="0"/>
    </joint>

    <link name="${prefix_finger}_r_link">
      <visual>
        <origin xyz="0.015 0.390481 -0.121822" rpy="1.570796327 0 0" />
        <geometry>
          <mesh filename="package://sobit_pro_description/meshes/gripper/sobit_pro_finger_r.dae"/>
        </geometry>
      </visual>
    </link>

    <joint name="${prefix_finger}_l_joint" type="revolute">
      <parent link="${prefix_grip}_inner_l_link" />
      <child link="${prefix_finger}_l_link" />
      <origin xyz="0 -0.080001 0" rpy="0 0 0" />
      <axis xyz="0 0 1" />
      <limit lower="-1.570796327" upper="0" effort="1" velocity="1"/>
      <mimic joint="${prefix_grip}_joint" multiplier="0.84" offset="0"/>
    </joint>

    <link name="${prefix_finger}_l_link">
      <visual>
        <origin xyz="-0.015 0.390481 -0.121822" rpy="1.570796327 0 0" />
        <geometry>
          <mesh filename="package://sobit_pro_description/meshes/gripper/sobit_pro_finger_l.dae"/>
        </geometry>
      </visual>
    </link>

    <xacro:gripper_transmission prefix="${prefix_grip}"/>

  </xacro:macro>
</robot>